<?xml version="1.0"?>
<robot name="diff_robot">


<material name="black">
    <color rgba="0 0 0 1.0"/>
</material>

<material name="grey">
    <color rgba="0.7 0.7 0.7 1.0"/>
</material>

<material name="green">
    <color rgba="0.0 0.6 0 1.0"/>
</material>

<material name="white">
    <color rgba="1 1 1 1.0"/>
</material>

<link name="base_footprint"/>


<link name="base_link">
    <inertial>
        <origin xyz="0.0 0.0 0.0" rpy="0.0 0.0 0.0"/>
        <mass value="3.0"/>
        <inertia ixx="0.05" ixy="0.0" ixz="0.0" iyy="0.1325" iyz="0.0" izz="0.1625"/>
    </inertial>
    <visual>
        <geometry>  
            <box size="0.7 0.4 0.2"/> 
        </geometry>   
        <origin xyz="0.0 0.0 0.1" rpy="0.0 0.0 0.0"/> 
        <material name="green"/>
    </visual>
</link>



<link name="left_wheel">
    <inertial>
        <origin xyz="0.0 0.0 0.0" rpy="0.0 0.0 0.0"/>
        <mass value="0.5"/>
        <inertia ixx="0.0013542" ixy="0.0" ixz="0.0" iyy="0.0013542" iyz="0.0" izz="0.0025"/>
    </inertial>
    <visual>
        <geometry>
            <cylinder radius="0.1" length="0.05"/>
        </geometry>
        <origin xyz="0.0 0.0 0.0" rpy="1.57 0.0 0.0"/>
        <material name="black"/>     
    </visual>
    <collision>
        <geometry>
            <cylinder radius="0.1" length="0.05"/>
        </geometry>
        <origin xyz="0.0 0.0 0.0" rpy="1.57 0.0 0.0"/>
    </collision>
</link>

<link name="right_wheel">
    <inertial>
        <origin xyz="0.0 0.0 0.0" rpy="0.0 0.0 0.0"/>
        <mass value="0.5"/>
        <inertia ixx="0.0013542" ixy="0.0" ixz="0.0" iyy="0.0013542" iyz="0.0" izz="0.0025"/>
    </inertial>
    <visual>
        <geometry>
            <cylinder radius="0.1" length="0.05"/>
        </geometry>
        <origin xyz="0.0 0.0 0.0" rpy="1.57 0.0 0.0"/>
        <material name="black"/>     
    </visual>
    <collision>
        <geometry>
            <cylinder radius="0.1" length="0.05"/>
        </geometry>
        <origin xyz="0.0 0.0 0.0" rpy="1.57 0.0 0.0"/>
    </collision>
</link>

<link name="caster_wheel">
    <inertial>
        <origin xyz="0.0 0.0 0.0" rpy="0.0 0.0 0.0"/>
        <mass value="0.5"/>
        <inertia ixx="0.0008333" ixy="0.0" ixz="0.0" iyy="0.0008333" iyz="0.0" izz="0.0008333"/>
    </inertial>
    <visual>
        <geometry>
                <sphere radius="0.05"/>
        </geometry>
        <origin xyz="0.0 0.0 0.0" rpy="0.0 0.0 0.0"/>
        <material name="black"/>            
    </visual>
    <collision>
        <geometry>
            <sphere radius="0.05"/>
        </geometry>
        <origin xyz="0.0 0.0 0.0" rpy="0.0 0.0 0.0"/>
    </collision>
</link>

<link name="imu_link">
  </link>



  <link name="lidar_link">
    <visual>
        <geometry>      
        <cylinder radius="0.1" length="0.05"/>
        <origin xyz="0.0 0.0 0.0" rpy="0.0 0.0 0.0"/>
        <material name="white"/>  
        </geometry> 
    </visual>
    <collision>
        <geometry>
            <cylinder radius="0.1" length="0.05"/>
        </geometry>
        <origin xyz="0.0 0.0 0.0" rpy="0.0 0.0 0.0"/>
    </collision>
    <inertial>
        <origin xyz="0.0 0.0 0.0" rpy="0.0 0.0 0.0"/>
        <mass value="0.5"/>
        <inertia ixx="0.0013542" ixy="0.0" ixz="0.0" iyy="0.0013542" iyz="0.0" izz="0.0025"/>
    </inertial>
  </link>


<joint name="imu_joint" type="fixed">
    <parent link="base_link"/>
    <child link="imu_link"/>
    <origin xyz="0.35 0.2 0.1" rpy="0.0 0.0 0.0"/>
</joint>

<joint name="base_joint" type="fixed">
    <parent link="base_footprint"/>
    <child link="base_link"/>
    <origin xyz="0.0 0.0 0.1" rpy="0.0 0.0 0.0"/>
</joint>

<joint name="base_lidar_joint" type="fixed">
    <parent link="base_link"/>
    <child link="lidar_link"/>
    <origin xyz="0.0 0.0 0.225" rpy="0.0 0.0 0.0"/>
</joint>

<joint name="left_wheel_joint" type="continuous">
    <parent link="base_link"/>
    <child link="left_wheel"/>
    <origin xyz="-0.175 0.225 0.0" rpy="0 0.0 0.0"/>  
    <axis xyz="0.0 1.0 0.0"/>
    <dynamics damping="0.2"/>
    <limit effort="100" velocity="1.0"/>
</joint>
<joint name="right_wheel_joint" type="continuous">
    <parent link="base_link"/>
    <child link="right_wheel"/>
    <origin xyz="-0.175 -0.225 0.0" rpy="0 0.0 0.0"/>  
    <axis xyz="0.0 1.0 0.0"/>
    <dynamics damping="0.2"/>
    <limit effort="100" velocity="1.0"/>
</joint>

<joint name="caster_wheel_joint" type="fixed">
    <parent link="base_link"/>
    <child link="caster_wheel"/>
    <origin xyz="0.2 0.0 -0.03" rpy="0.0 0.0 0.0"/>
</joint>



<gazebo>
    <plugin name="diff_drive" filename="libgazebo_ros_diff_drive.so">
        <!-- wheel info -->
        <left_joint>left_wheel_joint</left_joint>
        <right_joint>right_wheel_joint</right_joint>
        <wheel_separation>0.35</wheel_separation>
        <wheel_diameter>0.1</wheel_diameter>

        <!-- Limits -->
        <max_wheel_torque>200</max_wheel_torque>
        <max_wheel_acceleration>10.0</max_wheel_acceleration>

        <!-- Output -->
        <odometry_frame>odom</odometry_frame>
        <robot_base_frame>base_link</robot_base_frame>

        <publish_odom>true</publish_odom>
        <publish_odom_tf>true</publish_odom_tf>
        <publish_wheel_tf>true</publish_wheel_tf>
    </plugin>

    <plugin name="imu_plugin" filename="libgazebo_ros_imu.so">
        <alwaysOn>true</alwaysOn>
        <bodyName>imu_link</bodyName>
        <frameName>imu_link</frameName>
        <topicName>imu</topicName>
        <serviceName>imu_service</serviceName>
        <gaussianNoise>0.0</gaussianNoise>
        <updateRate>0</updateRate>
        <imu>
          <noise>
            <type>gaussian</type>
            <rate>
              <mean>0.0</mean>
              <stddev>2e-4</stddev>
              <bias_mean>0.0000075</bias_mean>
              <bias_stddev>0.0000008</bias_stddev>
            </rate>
            <accel>
              <mean>0.0</mean>
              <stddev>1.7e-2</stddev>
              <bias_mean>0.1</bias_mean>
              <bias_stddev>0.001</bias_stddev>
            </accel>
          </noise>
        </imu>
      </plugin>


      <plugin name="gazebo_ros_laser" filename="libgazebo_ros_laser.so">
        <robotNamespace>/my_robot</robotNamespace>
        <frameName>lidar_link</frameName>
        <topicName>/scan</topicName>
        <gaussianNoise>0.01</gaussianNoise>
        <updateRate>40</updateRate>
        <hokuyo>
          <minAngle>-1.5708</minAngle> <!-- -90 degrees -->
          <maxAngle>1.5708</maxAngle>  <!-- 90 degrees -->
          <minRange>0.1</minRange>
          <maxRange>30.0</maxRange>
          <resolution>0.00436332</resolution> <!-- 0.25 degrees -->
        </hokuyo>
      </plugin>
</gazebo>

<gazebo reference="base_link">
    <material>Gazebo/Green</material>
</gazebo>
<gazebo reference="right_wheel">
    <material>Gazebo/Black</material>
</gazebo>
<gazebo reference="left_wheel">
    <material>Gazebo/Black</material>
</gazebo>
<gazebo reference="caster_wheel">
    <material>Gazebo/Black</material>
</gazebo>


</robot>