<?xml version="1.0"?>
<robot name="diff_robot">


<material name="black">
    <color rgba="0 0 0 1.0"/>
</material>

<material name="grey">
    <color rgba="0.7 0.7 0.7 1.0"/>
</material>

<material name="green">
    <color rgba="0.0 0.6 0 1.0"/>
</material>

<material name="white">
    <color rgba="1 1 1 1.0"/>
</material>

<link name="base_footprint"/>


<link name="base_link">
    <inertial>
        <origin xyz="0.0 0.0 0.0" rpy="0.0 0.0 0.0"/>
        <mass value="1.0"/>
        <inertia ixx="0.05" ixy="0.0" ixz="0.0" iyy="0.1325" iyz="0.0" izz="0.1625"/>
    </inertial>
    <visual>
        <geometry>  
            <box size="0.7 0.4 0.2"/> 
        </geometry>   
        <origin xyz="0.0 0.0 0.1" rpy="0.0 0.0 0.0"/> 
        <material name="green"/>
    </visual>
</link>



<link name="left_wheel">
    <inertial>
        <origin xyz="0.0 0.0 0.0" rpy="0.0 0.0 0.0"/>
        <mass value="0.5"/>
        <inertia ixx="0.0013542" ixy="0.0" ixz="0.0" iyy="0.0013542" iyz="0.0" izz="0.0025"/>
    </inertial>
    <visual>
        <geometry>
            <cylinder radius="0.1" length="0.05"/>
        </geometry>
        <origin xyz="0.0 0.0 0.0" rpy="1.57 0.0 0.0"/>
        <material name="black"/>     
    </visual>
    <collision>
        <geometry>
            <cylinder radius="0.1" length="0.05"/>
        </geometry>
        <origin xyz="0.0 0.0 0.0" rpy="1.57 0.0 0.0"/>
        <surface>
            <!-- This friction pamareter don't contain reliable data!! -->
            <friction>
              <ode>
                <mu>100000.0</mu>
                <mu2>100000.0</mu2>
                <fdir1>0 0 0</fdir1>
                <slip1>0.0</slip1>
                <slip2>0.0</slip2>
              </ode>
            </friction>
            <contact>
              <ode>
                <soft_cfm>0</soft_cfm>
                <soft_erp>0.2</soft_erp>
                <kp>1e+5</kp>
                <kd>1</kd>
                <max_vel>0.01</max_vel>
                <min_depth>0.001</min_depth>
              </ode>
            </contact>
          </surface>
    </collision>
</link>

<link name="right_wheel">
    <inertial>
        <origin xyz="0.0 0.0 0.0" rpy="0.0 0.0 0.0"/>
        <mass value="0.5"/>
        <inertia ixx="0.0013542" ixy="0.0" ixz="0.0" iyy="0.0013542" iyz="0.0" izz="0.0025"/>
    </inertial>
    <visual>
        <geometry>
            <cylinder radius="0.1" length="0.05"/>
        </geometry>
        <origin xyz="0.0 0.0 0.0" rpy="1.57 0.0 0.0"/>
        <material name="black"/>     
    </visual>
    <collision>
        <geometry>
            <cylinder radius="0.1" length="0.05"/>
        </geometry>
        <surface>
            <!-- This friction pamareter don't contain reliable data!! -->
            <friction>
              <ode>
                <mu>100000.0</mu>
                <mu2>100000.0</mu2>
                <fdir1>0 0 0</fdir1>
                <slip1>0.0</slip1>
                <slip2>0.0</slip2>
              </ode>
            </friction>
            <contact>
              <ode>
                <soft_cfm>0</soft_cfm>
                <soft_erp>0.2</soft_erp>
                <kp>1e+5</kp>
                <kd>1</kd>
                <max_vel>0.01</max_vel>
                <min_depth>0.001</min_depth>
              </ode>
            </contact>
          </surface>
        <origin xyz="0.0 0.0 0.0" rpy="1.57 0.0 0.0"/>
    </collision>
</link>

<link name="caster_wheel">
    <inertial>
        <origin xyz="0.0 0.0 0.0" rpy="0.0 0.0 0.0"/>
        <mass value="0.5"/>
        <inertia ixx="0.0008333" ixy="0.0" ixz="0.0" iyy="0.0008333" iyz="0.0" izz="0.0008333"/>
    </inertial>
    <visual>
        <geometry>
                <sphere radius="0.05"/>
        </geometry>
        <origin xyz="0.0 0.0 0.0" rpy="0.0 0.0 0.0"/>
        <material name="black"/>            
    </visual>
    <collision>
        <geometry>
            <sphere radius="0.05"/>
        </geometry>
        <surface>
            <contact>
              <ode>
                <soft_cfm>0</soft_cfm>
                <soft_erp>0.2</soft_erp>
                <kp>1e+5</kp>
                <kd>1</kd>
                <max_vel>0.01</max_vel>
                <min_depth>0.001</min_depth>
              </ode>
            </contact>
          </surface>
        <origin xyz="0.0 0.0 0.0" rpy="0.0 0.0 0.0"/>
    </collision>
</link>

<link name="imu_link">
    <visual>
      <origin rpy="0 0 0" xyz="0 0 0.15815"/>
      <geometry>
        <box size="0.01 0.01 0.01"/>
      </geometry>
    </visual>
  </link>



  <link name="lidar_link">
    <visual>
        <geometry>      
        <cylinder radius="0.1" length="0.05"/>
        <origin xyz="0.0 0.0 0.0" rpy="0.0 0.0 0.0"/>
        <material name="white"/>  
        </geometry> 
    </visual>
    <collision>
        <geometry>
            <cylinder radius="0.05" length="0.05"/>
        </geometry>
        <origin xyz="0.0 0.0 0.0" rpy="0.0 0.0 0.0"/>
    </collision>
    <inertial>
        <origin xyz="0.0 0.0 0.0" rpy="0.0 0.0 0.0"/>
        <mass value="0.5"/>
        <inertia ixx="0.0013542" ixy="0.0" ixz="0.0" iyy="0.0013542" iyz="0.0" izz="0.0025"/>
    </inertial>
  </link>


<joint name="imu_joint" type="fixed">
    <parent link="base_link"/>
    <child link="imu_link"/>
    <origin xyz="0.35 0.2 0.1" rpy="0.0 0.0 0.0"/>
</joint>

<joint name="base_joint" type="fixed">
    <parent link="base_footprint"/>
    <child link="base_link"/>
    <origin xyz="0.0 0.0 0.05" rpy="0.0 0.0 0.0"/>
</joint>

<joint name="base_lidar_joint" type="fixed">
    <parent link="base_link"/>
    <child link="lidar_link"/>
    <origin xyz="0.0 0.0 0.225" rpy="0.0 0.0 0.0"/>
</joint>

<joint name="left_wheel_joint" type="continuous">
    <parent link="base_link"/>
    <child link="left_wheel"/>
    <origin xyz="-0.175 0.225 0.0" rpy="0 0.0 0.0"/>  
    <axis xyz="0.0 1.0 0.0"/>
    <dynamics damping="0.2" friction="1.0"/>
    <limit effort="1000" velocity="1000"/>
</joint>
<joint name="right_wheel_joint" type="continuous">
    <parent link="base_link"/>
    <child link="right_wheel"/>
    <origin xyz="-0.175 -0.225 0.0" rpy="0 0.0 0.0"/>  
    <axis xyz="0.0 1.0 0.0"/>
    <dynamics damping="0.2" friction="1.0"/>
    <limit effort="1000" velocity="1000"/>
</joint>

<joint name="caster_wheel_joint" type="fixed">
    <parent link="base_link"/>
    <child link="caster_wheel"/>
    <origin xyz="0.2 0.0 -0.03" rpy="0.0 0.0 0.0"/>
</joint>

<gazebo>
    <plugin name="diff_drive" filename="libgazebo_ros_diff_drive.so">
        <!-- wheel info -->
        <left_joint>left_wheel_joint</left_joint>
        <right_joint>right_wheel_joint</right_joint>
        <wheel_separation>0.4</wheel_separation>
        <wheel_diameter>0.1</wheel_diameter>

        <!-- Limits -->
        <max_wheel_torque>200</max_wheel_torque>
        <max_wheel_acceleration>10.0</max_wheel_acceleration>

        <!-- Output -->
        <odometry_frame>odom</odometry_frame>
        <robot_base_frame>base_link</robot_base_frame>

        <publish_odom>true</publish_odom>
        <publish_odom_tf>true</publish_odom_tf>
        <publish_wheel_tf>true</publish_wheel_tf>
    </plugin>
</gazebo>



<gazebo reference="imu_link">
    <sensor type="imu" name="imu">
      <always_on>true</always_on>
      <plugin filename="libgazebo_ros_imu_sensor.so" name="imu_plugin">
        <topicName>imu</topicName>
        <bodyName>imu_link</bodyName>
        <updateRateHZ>10.0</updateRateHZ>
        <gaussianNoise>0.0</gaussianNoise>
        <xyzOffset>0 0 0</xyzOffset>
        <rpyOffset>0 0 0</rpyOffset>
        <frameName>imu_link</frameName>
        <initialOrientationAsReference>false</initialOrientationAsReference>
      </plugin>
    </sensor>
  </gazebo>

  <gazebo reference="lidar_link">
    <sensor name="laser" type="ray">
        <pose> 0 0 0 0 0 0 </pose>
        <visualize>true</visualize>
        <update_rate>10</update_rate>
        <ray>
            <scan>
                <horizontal>
                    <samples>720</samples>
                    <min_angle>-3.14</min_angle>
                    <max_angle>3.14</max_angle>
                </horizontal>
            </scan>
            <range>
                <min>0.1</min>
                <max>12</max>
            </range>
        </ray>
        <plugin name="laser_controller" filename="libgazebo_ros_ray_sensor.so">
            <ros>
                <argument>~/out:=scan</argument>
            </ros>
            <output_type>sensor_msgs/LaserScan</output_type>
            <frame_name>lidar_link</frame_name>
        </plugin>
    </sensor>
</gazebo>

<gazebo>
    <plugin filename="libgazebo_ros2_control.so" name="gazebo_ros2_control">
      <robot_param>robot_description</robot_param>
      <robot_param_node>robot_state_publisher</robot_param_node>
      <parameters>/home/gursel/ros2_ws/src/diff_robot/control/diff_drive_controller.yaml</parameters>
    </plugin>
</gazebo>
<gazebo>
    <plugin name="diff_robot_joint_state" filename="libgazebo_ros_joint_state_publisher.so">
        <ros>
          <!-- <namespace>/tb3</namespace> -->
          <remapping>~/out:=joint_states</remapping>
        </ros>
        <update_rate>30</update_rate>
        <joint_name>left_wheel_joint</joint_name>
        <joint_name>right_wheel_joint</joint_name>
      </plugin>
    </gazebo>




<gazebo reference="base_link">
    <material>Gazebo/Green</material>
</gazebo>
<gazebo reference="right_wheel">
    <material>Gazebo/Black</material>
</gazebo>
<gazebo reference="left_wheel">
    <material>Gazebo/Black</material>
</gazebo>
<gazebo reference="caster_wheel">
    <material>Gazebo/Black</material>
</gazebo>


</robot>